
  0%|          | 0/20 [00:00<?, ?it/s]
  0%|          | 0/20 [02:02<?, ?it/s]
multiprocessing.pool.RemoteTraceback:
"""
Traceback (most recent call last):
  File "C:\Users\Danny Han\anaconda3\envs\ESE-5460_23\Lib\multiprocessing\pool.py", line 125, in worker
    result = (True, func(*args, **kwds))
                    ^^^^^^^^^^^^^^^^^^^
  File "C:\Users\Danny Han\anaconda3\envs\ESE-5460_23\Lib\multiprocessing\pool.py", line 48, in mapstar
    return list(map(*args))
           ^^^^^^^^^^^^^^^^
  File "C:\Users\Danny Han\Desktop\alphazero-sudoku\Train.py", line 75, in playGame
    data = p.playGame()
           ^^^^^^^^^^^^
  File "C:\Users\Danny Han\Desktop\alphazero-sudoku\Play.py", line 29, in playGame
    pi = self.mcts.getActionProb(board, temp=temp)
         ^^^^^^^^^^^^^^^^^^^^^^^^^^^^^^^^^^^^^^^^^
  File "C:\Users\Danny Han\Desktop\alphazero-sudoku\MCTS.py", line 39, in getActionProb
    self.search(board)
  File "C:\Users\Danny Han\Desktop\alphazero-sudoku\MCTS.py", line 128, in search
    v = self.search(next_s)
        ^^^^^^^^^^^^^^^^^^^
  File "C:\Users\Danny Han\Desktop\alphazero-sudoku\MCTS.py", line 128, in search
    v = self.search(next_s)
        ^^^^^^^^^^^^^^^^^^^
  File "C:\Users\Danny Han\Desktop\alphazero-sudoku\MCTS.py", line 83, in search
    self.Ps[s], v = self.nnet.predict(SudokuGame.two_dim_to_three_dim(board))
                    ^^^^^^^^^^^^^^^^^^^^^^^^^^^^^^^^^^^^^^^^^^^^^^^^^^^^^^^^^
  File "C:\Users\Danny Han\Desktop\alphazero-sudoku\NNet.py", line 132, in predict
    return torch.exp(pi).data.cpu().numpy()[0], v.data.cpu().numpy()[0]
           ^^^^^^^^^^^^^^^^^^^^^^^^
RuntimeError: CUDA error: unknown error
CUDA kernel errors might be asynchronously reported at some other API call, so the stacktrace below might be incorrect.
For debugging consider passing CUDA_LAUNCH_BLOCKING=1.
Compile with `TORCH_USE_CUDA_DSA` to enable device-side assertions.
"""
The above exception was the direct cause of the following exception:
Traceback (most recent call last):
  File "C:\Users\Danny Han\Desktop\alphazero-sudoku\main.py", line 40, in <module>
    main()
  File "C:\Users\Danny Han\Desktop\alphazero-sudoku\main.py", line 36, in main
    t.learn()
  File "C:\Users\Danny Han\Desktop\alphazero-sudoku\Train.py", line 58, in learn
    data = p.map(playGame, plays)
           ^^^^^^^^^^^^^^^^^^^^^^
  File "C:\Users\Danny Han\anaconda3\envs\ESE-5460_23\Lib\multiprocessing\pool.py", line 367, in map
    return self._map_async(func, iterable, mapstar, chunksize).get()
           ^^^^^^^^^^^^^^^^^^^^^^^^^^^^^^^^^^^^^^^^^^^^^^^^^^^^^^^^^
  File "C:\Users\Danny Han\anaconda3\envs\ESE-5460_23\Lib\multiprocessing\pool.py", line 774, in get
    raise self._value
RuntimeError: CUDA error: unknown error
CUDA kernel errors might be asynchronously reported at some other API call, so the stacktrace below might be incorrect.
For debugging consider passing CUDA_LAUNCH_BLOCKING=1.
Compile with `TORCH_USE_CUDA_DSA` to enable device-side assertions.