
  0%|          | 0/50 [00:00<?, ?it/s]
  0%|          | 0/50 [00:13<?, ?it/s]
multiprocessing.pool.RemoteTraceback:
"""
Traceback (most recent call last):
  File "C:\Users\Danny Han\anaconda3\envs\ESE-5460_23\Lib\multiprocessing\pool.py", line 125, in worker
    result = (True, func(*args, **kwds))
                    ^^^^^^^^^^^^^^^^^^^
  File "C:\Users\Danny Han\anaconda3\envs\ESE-5460_23\Lib\multiprocessing\pool.py", line 48, in mapstar
    return list(map(*args))
           ^^^^^^^^^^^^^^^^
  File "C:\Users\Danny Han\Desktop\alphazero-sudoku\Train.py", line 69, in playGame
    data = p.playGame()
           ^^^^^^^^^^^^
  File "C:\Users\Danny Han\Desktop\alphazero-sudoku\Play.py", line 29, in playGame
    pi = self.mcts.getActionProb(board, temp=temp)
         ^^^^^^^^^^^^^^^^^^^^^^^^^^^^^^^^^^^^^^^^^
  File "C:\Users\Danny Han\Desktop\alphazero-sudoku\MCTS.py", line 39, in getActionProb
    self.search(board)
  File "C:\Users\Danny Han\Desktop\alphazero-sudoku\MCTS.py", line 129, in search
    assert not np.all(temp == next_s)
AssertionError
"""
The above exception was the direct cause of the following exception:
Traceback (most recent call last):
  File "C:\Users\Danny Han\Desktop\alphazero-sudoku\main.py", line 40, in <module>
    main()
  File "C:\Users\Danny Han\Desktop\alphazero-sudoku\main.py", line 36, in main
    t.learn()
  File "C:\Users\Danny Han\Desktop\alphazero-sudoku\Train.py", line 56, in learn
    data = p.map(playGame, plays)
           ^^^^^^^^^^^^^^^^^^^^^^
  File "C:\Users\Danny Han\anaconda3\envs\ESE-5460_23\Lib\multiprocessing\pool.py", line 367, in map
    return self._map_async(func, iterable, mapstar, chunksize).get()
           ^^^^^^^^^^^^^^^^^^^^^^^^^^^^^^^^^^^^^^^^^^^^^^^^^^^^^^^^^
  File "C:\Users\Danny Han\anaconda3\envs\ESE-5460_23\Lib\multiprocessing\pool.py", line 774, in get
    raise self._value
AssertionError